package com.aurionpro.test;

import static org.junit.jupiter.api.Assertions.assertEquals;
import static org.junit.jupiter.api.Assertions.assertThrows;

import org.junit.jupiter.api.Disabled;
import org.junit.jupiter.api.RepeatedTest;
import org.junit.jupiter.api.Tag;
import org.junit.jupiter.api.Test;

import com.aurionpro.model.Calculator;

public class calculatorTest {

	Calculator cal = new Calculator();

	@Test
	public void testAddition() {

		int sum = cal.addition(10, 2);
		assertEquals(12, sum);
	}

	@Test
	@Disabled
//	    @RepeatedTest(5)
	@RepeatedTest(name = "Running {currentRepetition} of {totalRepetitions}", value=5)
	public void testSubtraction() {
		assertEquals(8, cal.subtraction(10, 2));
	}

	@Test
	public void testDivision() {
		// assertEquals(2, cal.division(10,0)); // this will not catch exception it will give failure .
		assertThrows(ArithmeticException.class, () -> cal.divison(5, 0));
	}

	@Test
	    @Tag("Slow")
	    public void underDevelopment()
	    {
	        System.out.println("Under progress.....can not be tested");
	    }

}
